Workbook

Sheet Инструкция
A1: Анализ ответов опросника директоров филиалов — ДУП
A3: 1. Сбор ответов в Google Forms
A4: • Создайте форму по файлу DUP_oprosnik_Google_Forms_инструкция.md
A5: • В Google Forms: Ответы → Создать таблицу (Google Таблицы) ИЛИ скачать CSV (.csv)
A7: 2. Импорт в этот файл
A8: • Вариант A: Скопируйте все строки из Google Таблицы на лист «Сырые ответы» (начиная со строки 2, без заголовков — они уже есть)
A9: • Вариант B: Запустите: python3 import_survey_responses.py путь/к/ответы.csv
A10: • Вариант C: В Excel — Данные → Из текста/CSV → лист «Сырые ответы»
A12: 3. Автообновление сводки
A13: • Листы «Дашборд», «Шкалы», «Взаимодействие ЦО», «ТОП боли», «Интервью» обновляются по формулам при заполнении «Сырые ответы»
A14: • Красная зона: средняя оценка по шкале ≤ 2,5
A16: 4. Столбцы на листе «Сырые ответы»
... A19: • Для шкал указывайте число 1–5

Sheet Сырые ответы
A1: Дата ответа | B1: Регион/филиал | C1: Должность | D1: ФИО (опц.) | E1: A1: Ваш регион / филиал | F1: A2: Ваша должность | G1: A3: Сколько действующих проектов ГЧП/ГЗ сейчас ведёт ф | H1: A4: Сколько сотрудников в проектной/операционной коман | I1: A5: Как часто вы взаимодействуете с куратором/менеджер | J1: A6: Знаете ли вы, кто является вашим закреплённым кура | K1: B1: Насколько понятен вам процесс запуска нового проек | L1: B2: Как вы обычно получаете новый проект от ДУП / ДРБ? | M1: B3: Достаточно ли полным приходит пакет документов при | N1: B4: Какие документы чаще всего отсутствуют или приходя | O1: B5: Сколько в среднем занимает подготовка проектной до | P1: B6: Насколько сложно согласовать бюджет проекта с Финб | Q1: B7: Как часто закупочные процедуры (выше упрощённого п | R1: B8: Оцените среднюю длительность закупочной процедуры | S1: B9: Проводятся ли регулярные статус-встречи по проекта | T1: B10: Кто чаще всего инициирует и ведёт статус-встречи п | U1: B11: Опишите 1–2 типичных блокера на этапе реализации в | V1: C1: Насколько понятен процесс сопровождения действующи | W1: C2: Какие задачи сопровождения выполняет филиал самост | X1: C3: Насколько своевременно ДУП реагирует на операционн | Y1: C4: Сталкивались ли вы с ситуацией, когда продукт/обор | Z1: C5: Если да — к чему это приводило? (можно несколько) | AA1: C6: Насколько налажен процесс передачи информации о де | AB1: C7: Как часто филиал инициирует продление или модерниз | AC1: C8: Опишите главную боль в операционном сопровождении | AD1: D1: Кто в филиале формирует реестр платежей? | AE1: D2: Насколько понятен процесс приоритизации платежей ( | AF1: D3: Как часто платежи по вашим заявкам задерживаются д | AG1: D4: Какова типичная причина задержки оплат? (можно нес | AH1: D5: Участвует ли филиал в прогнозе поступлений доходов | AI1: D6: Насколько удобен текущий формат обмена данными по | AJ1: D7: Сталкивались ли с ситуацией нехватки бюджета проек | AK1: D8: Если да — как решался вопрос? | AL1: E1: Насколько чётко разграничены зоны ответственности | AM1: E2: Понимаете ли вы, к кому в ДУП обращаться по разным | AN1: E3: Как вы оцениваете качество коммуникации с кураторо | AO1: E4: Какие каналы связи с ДУП используются чаще всего? | AP1: E5: Бывали ли случаи эскалации проблем в обход ДУП нап | AQ1: E6: Участвовал ли филиал в открытии нового филиала / р | AR1: E7: Если да — насколько понятен был процесс и кто коор | AS1: E8: Что бы вы улучшили во взаимодействии с ДУП в перву | AT1: F1_ДРБ: Оцените взаимодействие филиала с подразделениями ( | AU1: F1_Финблок: Оцените взаимодействие филиала с подразделениями ( | AV1: F1_Юр_блок: Оцените взаимодействие филиала с подразделениями ( | AW1: F1_Закупки_(ОЛЖА): Оцените взаимодействие филиала с подразделениями ( | AX1: F1_СТ_(тех._блок): Оцените взаимодействие филиала с подразделениями ( | AY1: F1_Зерек_/_Zerek_R: Оцените взаимодействие филиала с подразделениями ( | AZ1: F1_HR: Оцените взаимодействие филиала с подразделениями ( | BA1: F1_Лаборатория_(по: Оцените взаимодействие филиала с подразделениями ( | BB1: F2: С каким подразделением ЦО чаще всего возникают зад | BC1: F3: Насколько своевременно ДРБ передаёт проекты с полн | BD1: F4: Насколько оперативно Юр блок сопровождает договоры | BE1: F5: Опишите типичную проблему во взаимодействии с цент | BF1: G1: Какие инструменты вы используете в ежедневной прое | BG1: G2: Насколько полноценно работает платформа портфеля п | BH1: G3: Чего не хватает в текущих IT-инструментах для ваше | BI1: G4: Сколько времени в неделю уходит на ручной сбор дан | BJ1: H1: Назовите ТОП-3 проблемы в процессах, которые сильн | BK1: H2: Назовите ТОП-3 процесса, которые нужно автоматизир | BL1: H3: Если бы вы могли изменить одну вещь в работе ДУП и | BM1: H4: Готовы ли вы участвовать в 30–45-минутном углублён | BN1: H5: Контакт для связи (email / телефон) — если готовы
A2: 2026-08-19 | B2: Алматы | C2: Директор филиала | K2: 2 | M2: 4 | P2: 4 | V2: 3 | X2: 2 | AA2: 3 | AE2: 2 | AI2: 3 | AL2: 2 | AM2: 2 | AN2: 2 | AT2: 3 | AU2: 2 | AV2: 3 | AW2: 3 | AX2: 5 | AY2: 2 | AZ2: 3 | BA2: 2 | BC2: 3 | BD2: 4 | BG2: 3 | BJ2: Задержки закупок; неполный пакет от ДРБ; хаос в прогнозе поступлений | BM2: Да
A3: 2026-08-17 | B3: Туркестан | C3: Главный инженер | K3: 2 | M3: 4 | P3: 4 | V3: 3 | X3: 2 | AA3: 2 | AE3: 2 | AI3: 4 | AL3: 3 | AM3: 3 | AN3: 2 | AT3: 4 | AU3: 5 | AV3: 4 | AW3: 5 | AX3: 2 | AY3: 2 | AZ3: 2 | BA3: 4 | BC3: 2 | BD3: 2 | BG3: 2 | BJ3: Задержки закупок; неполный пакет от ДРБ; хаос в прогнозе поступлений | BM3: Возможно, по согласованию
A4: 2026-08-15 | B4: Астана | C4: Региональный менеджер проекта | K4: 2 | M4: 2 | P4: 2 | V4: 3 | X4: 2 | AA4: 4 | AE4: 2 | AI4: 4 | AL4: 2 | AM4: 4 | AN4: 2 | AT4: 2 | AU4: 3 | AV4: 2 | AW4: 5 | AX4: 2 | AY4: 3 | AZ4: 2 | BA4: 4 | BC4: 4 | BD4: 4 | BG4: 3 | BJ4: Задержки закупок; неполный пакет от ДРБ; хаос в прогнозе поступлений | BM4: Возможно, по согласованию
A5: 2026-08-13 | B5: Тараз | C5: Директор филиала | K5: 4 | M5: 3 | P5: 3 | V5: 3 | X5: 2 | AA5: 3 | AE5: 3 | AI5: 2 | AL5: 3 | AM5: 4 | AN5: 2 | AT5: 5 | AU5: 3 | AV5: 2 | AW5: 2 | AX5: 2 | AY5: 2 | AZ5: 4 | BA5: 5 | BC5: 4 | BD5: 3 | BG5: 3 | BJ5: Задержки закупок; неполный пакет от ДРБ; хаос в прогнозе поступлений | BM5: Да
A6: 2026-08-11 | B6: Шымкент | C6: Заместитель директора филиала | K6: 4 | M6: 4 | P6: 3 | V6: 3 | X6: 4 | AA6: 2 | AE6: 3 | AI6: 4 | AL6: 4 | AM6: 2 | AN6: 4 | AT6: 2 | AU6: 5 | AV6: 5 | AW6: 5 | AX6: 4 | AY6: 3 | AZ6: 2 | BA6: 3 | BC6: 3 | BD6: 4 | BG6: 4 | BJ6: Задержки закупок; неполный пакет от ДРБ; хаос в прогнозе поступлений | BM6: Да

Sheet Карта вопросов
A1: ID | B1: Текст вопроса | C1: Тип | D1: Столбец в «Сырые ответы» | E1: Участвует в сводке
A2: A1 | B2: Ваш регион / филиал | C2: текст | D2: E | E2: —
A3: A2 | B3: Ваша должность | C3: один из списка | D3: F | E3: Распределение
A4: A3 | B4: Сколько действующих проектов ГЧП/ГЗ сейчас ведёт филиал? | C4: один из списка | D4: G | E4: Распределение
A5: A4 | B5: Сколько сотрудников в проектной/операционной команде филиала (приблизительно)? | C5: один из списка | D5: H | E5: Распределение
A6: A5 | B6: Как часто вы взаимодействуете с куратором/менеджером проекта со стороны ДУП? | C6: один из списка | D6: I | E6: Распределение
A7: A6 | B7: Знаете ли вы, кто является вашим закреплённым куратором в ДУП (ФИО)? | C7: да/нет | D7: J | E7: Распределение
A8: B1 | B8: Насколько понятен вам процесс запуска нового проекта в филиале (от получения поручения до сдачи объекта)? | C8: шкала 1–5 | D8: K | E8: Шкала
A9: B2 | B9: Как вы обычно получаете новый проект от ДУП / ДРБ? | C9: несколько из списка | D9: L | E9: —
A10: B3 | B10: Достаточно ли полным приходит пакет документов при старте проекта (договор, ФЭМ, ТЗ, адресная программа и т.д.)? | C10: шкала 1–5 | D10: M | E10: Шкала
A11: B4 | B11: Какие документы чаще всего отсутствуют или приходят с задержкой? (можно несколько) | C11: несколько из списка | D11: N | E11: —
A12: B5 | B12: Сколько в среднем занимает подготовка проектной документации филиалом (устав, план, приказ)? | C12: один из списка | D12: O | E12: Распределение
... A63: H5 | B63: Контакт для связи (email / телефон) — если готовы к интервью | C63: текст | D63: BN | E63: —

Sheet Дашборд
A1: Сводный дашборд — опрос директоров филиалов
A3: Количество ответов | B3: =COUNTA('Сырые ответы'!B:B)-1
A4: Дата последнего обновления | B4: =TODAY()
A6: Показатель | B6: Среднее | C6: Зона | D6: Комментарий
A7: Понятность процесса реализации | B7: =IFERROR(AVERAGE('Сырые ответы'!K2:K500),"") | C7: =IF(B7="","—",IF(B7<=2.5,"🔴 Критично",IF(B7<=3.5,"🟡 Внимание","🟢 Норма"))) | D7: Вопрос B1
A8: Полнота пакета документов при старте | B8: =IFERROR(AVERAGE('Сырые ответы'!M2:M500),"") | C8: =IF(B8="","—",IF(B8<=2.5,"🔴 Критично",IF(B8<=3.5,"🟡 Внимание","🟢 Норма"))) | D8: Вопрос B3
A9: Согласование бюджета с Финблоком | B9: =IFERROR(AVERAGE('Сырые ответы'!P2:P500),"") | C9: =IF(B9="","—",IF(B9<=2.5,"🔴 Критично",IF(B9<=3.5,"🟡 Внимание","🟢 Норма"))) | D9: Вопрос B6
A10: Понятность сопровождения | B10: =IFERROR(AVERAGE('Сырые ответы'!V2:V500),"") | C10: =IF(B10="","—",IF(B10<=2.5,"🔴 Критично",IF(B10<=3.5,"🟡 Внимание","🟢 Норма"))) | D10: Вопрос C1
A11: Скорость реакции ДУП на проблемы | B11: =IFERROR(AVERAGE('Сырые ответы'!X2:X500),"") | C11: =IF(B11="","—",IF(B11<=2.5,"🔴 Критично",IF(B11<=3.5,"🟡 Внимание","🟢 Норма"))) | D11: Вопрос C3
A12: Обратная связь по дефектам компонентов | B12: =IFERROR(AVERAGE('Сырые ответы'!AA2:AA500),"") | C12: =IF(B12="","—",IF(B12<=2.5,"🔴 Критично",IF(B12<=3.5,"🟡 Внимание","🟢 Норма"))) | D12: Вопрос C6
A13: Понятность приоритизации платежей | B13: =IFERROR(AVERAGE('Сырые ответы'!AE2:AE500),"") | C13: =IF(B13="","—",IF(B13<=2.5,"🔴 Критично",IF(B13<=3.5,"🟡 Внимание","🟢 Норма"))) | D13: Вопрос D2
A14: Удобство прогноза поступлений/расходов | B14: =IFERROR(AVERAGE('Сырые ответы'!AI2:AI500),"") | C14: =IF(B14="","—",IF(B14<=2.5,"🔴 Критично",IF(B14<=3.5,"🟡 Внимание","🟢 Норма"))) | D14: Вопрос D6
A15: Разграничение ответственности филиал/ДУП | B15: =IFERROR(AVERAGE('Сырые ответы'!AL2:AL500),"") | C15: =IF(B15="","—",IF(B15<=2.5,"🔴 Критично",IF(B15<=3.5,"🟡 Внимание","🟢 Норма"))) | D15: Вопрос E1
A16: Понятность, к кому обращаться в ДУП | B16: =IFERROR(AVERAGE('Сырые ответы'!AM2:AM500),"") | C16: =IF(B16="","—",IF(B16<=2.5,"🔴 Критично",IF(B16<=3.5,"🟡 Внимание","🟢 Норма"))) | D16: Вопрос E2
A17: Качество коммуникации с куратором | B17: =IFERROR(AVERAGE('Сырые ответы'!AN2:AN500),"") | C17: =IF(B17="","—",IF(B17<=2.5,"🔴 Критично",IF(B17<=3.5,"🟡 Внимание","🟢 Норма"))) | D17: Вопрос E3
A18: Своевременность передачи от ДРБ | B18: =IFERROR(AVERAGE('Сырые ответы'!BC2:BC500),"") | C18: =IF(B18="","—",IF(B18<=2.5,"🔴 Критично",IF(B18<=3.5,"🟡 Внимание","🟢 Норма"))) | D18: Вопрос F3
A19: Оперативность Юр блока | B19: =IFERROR(AVERAGE('Сырые ответы'!BD2:BD500),"") | C19: =IF(B19="","—",IF(B19<=2.5,"🔴 Критично",IF(B19<=3.5,"🟡 Внимание","🟢 Норма"))) | D19: Вопрос F4
A20: Работоспособность платформы проектов | B20: =IFERROR(AVERAGE('Сырые ответы'!BG2:BG500),"") | C20: =IF(B20="","—",IF(B20<=2.5,"🔴 Критично",IF(B20<=3.5,"🟡 Внимание","🟢 Норма"))) | D20: Вопрос G2

Sheet Шкалы
A1: Детализация по шкалам 1–5 (распределение ответов)
A3: ID | B3: Вопрос | C3: 1 | D3: 2 | E3: 3 | F3: 4 | G3: 5 | H3: Среднее | I3: N
A4: B1 | B4: Насколько понятен вам процесс запуска нового проекта в филиале (от получения поручения до сдачи объекта)? | C4: =COUNTIF('Сырые ответы'!K2:K500,1) | D4: =COUNTIF('Сырые ответы'!K2:K500,2) | E4: =COUNTIF('Сырые ответы'!K2:K500,3) | F4: =COUNTIF('Сырые ответы'!K2:K500,4) | G4: =COUNTIF('Сырые ответы'!K2:K500,5) | H4: =IFERROR(AVERAGE('Сырые ответы'!K2:K500),"") | I4: =COUNT('Сырые ответы'!K2:K500)
A5: B3 | B5: Достаточно ли полным приходит пакет документов при старте проекта (договор, ФЭМ, ТЗ, адресная программа и т.д.)? | C5: =COUNTIF('Сырые ответы'!M2:M500,1) | D5: =COUNTIF('Сырые ответы'!M2:M500,2) | E5: =COUNTIF('Сырые ответы'!M2:M500,3) | F5: =COUNTIF('Сырые ответы'!M2:M500,4) | G5: =COUNTIF('Сырые ответы'!M2:M500,5) | H5: =IFERROR(AVERAGE('Сырые ответы'!M2:M500),"") | I5: =COUNT('Сырые ответы'!M2:M500)
A6: B6 | B6: Насколько сложно согласовать бюджет проекта с Финблоком через ДУП? | C6: =COUNTIF('Сырые ответы'!P2:P500,1) | D6: =COUNTIF('Сырые ответы'!P2:P500,2) | E6: =COUNTIF('Сырые ответы'!P2:P500,3) | F6: =COUNTIF('Сырые ответы'!P2:P500,4) | G6: =COUNTIF('Сырые ответы'!P2:P500,5) | H6: =IFERROR(AVERAGE('Сырые ответы'!P2:P500),"") | I6: =COUNT('Сырые ответы'!P2:P500)
A7: C1 | B7: Насколько понятен процесс сопровождения действующих проектов после ввода в эксплуатацию? | C7: =COUNTIF('Сырые ответы'!V2:V500,1) | D7: =COUNTIF('Сырые ответы'!V2:V500,2) | E7: =COUNTIF('Сырые ответы'!V2:V500,3) | F7: =COUNTIF('Сырые ответы'!V2:V500,4) | G7: =COUNTIF('Сырые ответы'!V2:V500,5) | H7: =IFERROR(AVERAGE('Сырые ответы'!V2:V500),"") | I7: =COUNT('Сырые ответы'!V2:V500)
A8: C3 | B8: Насколько своевременно ДУП реагирует на операционные проблемы (инциденты, простои, претензии госпартнёра)? | C8: =COUNTIF('Сырые ответы'!X2:X500,1) | D8: =COUNTIF('Сырые ответы'!X2:X500,2) | E8: =COUNTIF('Сырые ответы'!X2:X500,3) | F8: =COUNTIF('Сырые ответы'!X2:X500,4) | G8: =COUNTIF('Сырые ответы'!X2:X500,5) | H8: =IFERROR(AVERAGE('Сырые ответы'!X2:X500),"") | I8: =COUNT('Сырые ответы'!X2:X500)
A9: C6 | B9: Насколько налажен процесс передачи информации о дефектах компонентов (от монтажников/эксплуатации к закупкам/ТЗ)? | C9: =COUNTIF('Сырые ответы'!AA2:AA500,1) | D9: =COUNTIF('Сырые ответы'!AA2:AA500,2) | E9: =COUNTIF('Сырые ответы'!AA2:AA500,3) | F9: =COUNTIF('Сырые ответы'!AA2:AA500,4) | G9: =COUNTIF('Сырые ответы'!AA2:AA500,5) | H9: =IFERROR(AVERAGE('Сырые ответы'!AA2:AA500),"") | I9: =COUNT('Сырые ответы'!AA2:AA500)
A10: D2 | B10: Насколько понятен процесс приоритизации платежей (филиал → ДУП → Финблок)? | C10: =COUNTIF('Сырые ответы'!AE2:AE500,1) | D10: =COUNTIF('Сырые ответы'!AE2:AE500,2) | E10: =COUNTIF('Сырые ответы'!AE2:AE500,3) | F10: =COUNTIF('Сырые ответы'!AE2:AE500,4) | G10: =COUNTIF('Сырые ответы'!AE2:AE500,5) | H10: =IFERROR(AVERAGE('Сырые ответы'!AE2:AE500),"") | I10: =COUNT('Сырые ответы'!AE2:AE500)
A11: D6 | B11: Насколько удобен текущий формат обмена данными по прогнозу поступлений/расходов с Финблоком? | C11: =COUNTIF('Сырые ответы'!AI2:AI500,1) | D11: =COUNTIF('Сырые ответы'!AI2:AI500,2) | E11: =COUNTIF('Сырые ответы'!AI2:AI500,3) | F11: =COUNTIF('Сырые ответы'!AI2:AI500,4) | G11: =COUNTIF('Сырые ответы'!AI2:AI500,5) | H11: =IFERROR(AVERAGE('Сырые ответы'!AI2:AI500),"") | I11: =COUNT('Сырые ответы'!AI2:AI500)
A12: E1 | B12: Насколько чётко разграничены зоны ответственности между филиалом и ДУП? | C12: =COUNTIF('Сырые ответы'!AL2:AL500,1) | D12: =COUNTIF('Сырые ответы'!AL2:AL500,2) | E12: =COUNTIF('Сырые ответы'!AL2:AL500,3) | F12: =COUNTIF('Сырые ответы'!AL2:AL500,4) | G12: =COUNTIF('Сырые ответы'!AL2:AL500,5) | H12: =IFERROR(AVERAGE('Сырые ответы'!AL2:AL500),"") | I12: =COUNT('Сырые ответы'!AL2:AL500)
A13: E2 | B13: Понимаете ли вы, к кому в ДУП обращаться по разным типам вопросов (реализация / сопровождение / финансы / методология)? | C13: =COUNTIF('Сырые ответы'!AM2:AM500,1) | D13: =COUNTIF('Сырые ответы'!AM2:AM500,2) | E13: =COUNTIF('Сырые ответы'!AM2:AM500,3) | F13: =COUNTIF('Сырые ответы'!AM2:AM500,4) | G13: =COUNTIF('Сырые ответы'!AM2:AM500,5) | H13: =IFERROR(AVERAGE('Сырые ответы'!AM2:AM500),"") | I13: =COUNT('Сырые ответы'!AM2:AM500)
A14: E3 | B14: Как вы оцениваете качество коммуникации с куратором ДУП? | C14: =COUNTIF('Сырые ответы'!AN2:AN500,1) | D14: =COUNTIF('Сырые ответы'!AN2:AN500,2) | E14: =COUNTIF('Сырые ответы'!AN2:AN500,3) | F14: =COUNTIF('Сырые ответы'!AN2:AN500,4) | G14: =COUNTIF('Сырые ответы'!AN2:AN500,5) | H14: =IFERROR(AVERAGE('Сырые ответы'!AN2:AN500),"") | I14: =COUNT('Сырые ответы'!AN2:AN500)
A15: F3 | B15: Насколько своевременно ДРБ передаёт проекты с полным пакетом документов? | C15: =COUNTIF('Сырые ответы'!BC2:BC500,1) | D15: =COUNTIF('Сырые ответы'!BC2:BC500,2) | E15: =COUNTIF('Сырые ответы'!BC2:BC500,3) | F15: =COUNTIF('Сырые ответы'!BC2:BC500,4) | G15: =COUNTIF('Сырые ответы'!BC2:BC500,5) | H15: =IFERROR(AVERAGE('Сырые ответы'!BC2:BC500),"") | I15: =COUNT('Сырые ответы'!BC2:BC500)
A16: F4 | B16: Насколько оперативно Юр блок сопровождает договоры и открытие филиала? | C16: =COUNTIF('Сырые ответы'!BD2:BD500,1) | D16: =COUNTIF('Сырые ответы'!BD2:BD500,2) | E16: =COUNTIF('Сырые ответы'!BD2:BD500,3) | F16: =COUNTIF('Сырые ответы'!BD2:BD500,4) | G16: =COUNTIF('Сырые ответы'!BD2:BD500,5) | H16: =IFERROR(AVERAGE('Сырые ответы'!BD2:BD500),"") | I16: =COUNT('Сырые ответы'!BD2:BD500)
A17: G2 | B17: Насколько полноценно работает платформа портфеля проектов (документация, бюджет план/факт, риски, задачи)? | C17: =COUNTIF('Сырые ответы'!BG2:BG500,1) | D17: =COUNTIF('Сырые ответы'!BG2:BG500,2) | E17: =COUNTIF('Сырые ответы'!BG2:BG500,3) | F17: =COUNTIF('Сырые ответы'!BG2:BG500,4) | G17: =COUNTIF('Сырые ответы'!BG2:BG500,5) | H17: =IFERROR(AVERAGE('Сырые ответы'!BG2:BG500),"") | I17: =COUNT('Сырые ответы'!BG2:BG500)

Sheet Взаимодействие ЦО
A1: Оценки взаимодействия с подразделениями ЦО (вопрос F1)
A3: Подразделение | B3: Средняя оценка | C3: N ответов | D3: Зона
A4: ДРБ | B4: =IFERROR(AVERAGE('Сырые ответы'!AT2:AT500),"") | C4: =COUNT('Сырые ответы'!AT2:AT500) | D4: =IF(B4="","—",IF(B4<=2.5,"🔴",IF(B4<=3.5,"🟡","🟢")))
A5: Финблок | B5: =IFERROR(AVERAGE('Сырые ответы'!AU2:AU500),"") | C5: =COUNT('Сырые ответы'!AU2:AU500) | D5: =IF(B5="","—",IF(B5<=2.5,"🔴",IF(B5<=3.5,"🟡","🟢")))
A6: Юр блок | B6: =IFERROR(AVERAGE('Сырые ответы'!AV2:AV500),"") | C6: =COUNT('Сырые ответы'!AV2:AV500) | D6: =IF(B6="","—",IF(B6<=2.5,"🔴",IF(B6<=3.5,"🟡","🟢")))
A7: Закупки (ОЛЖА) | B7: =IFERROR(AVERAGE('Сырые ответы'!AW2:AW500),"") | C7: =COUNT('Сырые ответы'!AW2:AW500) | D7: =IF(B7="","—",IF(B7<=2.5,"🔴",IF(B7<=3.5,"🟡","🟢")))
A8: СТ (тех. блок) | B8: =IFERROR(AVERAGE('Сырые ответы'!AX2:AX500),"") | C8: =COUNT('Сырые ответы'!AX2:AX500) | D8: =IF(B8="","—",IF(B8<=2.5,"🔴",IF(B8<=3.5,"🟡","🟢")))
A9: Зерек / Zerek Road tech | B9: =IFERROR(AVERAGE('Сырые ответы'!AY2:AY500),"") | C9: =COUNT('Сырые ответы'!AY2:AY500) | D9: =IF(B9="","—",IF(B9<=2.5,"🔴",IF(B9<=3.5,"🟡","🟢")))
A10: HR | B10: =IFERROR(AVERAGE('Сырые ответы'!AZ2:AZ500),"") | C10: =COUNT('Сырые ответы'!AZ2:AZ500) | D10: =IF(B10="","—",IF(B10<=2.5,"🔴",IF(B10<=3.5,"🟡","🟢")))
A11: Лаборатория (поверка) | B11: =IFERROR(AVERAGE('Сырые ответы'!BA2:BA500),"") | C11: =COUNT('Сырые ответы'!BA2:BA500) | D11: =IF(B11="","—",IF(B11<=2.5,"🔴",IF(B11<=3.5,"🟡","🟢")))

Sheet Распределения
A1: Ключевые категориальные вопросы — частота ответов
A3: B7: Задержки закупок
A4: Вариант ответа | B4: Кол-во | C4: %
A7: D3: Задержки платежей
A8: Вариант ответа | B8: Кол-во | C8: %
A11: D5: Участие в прогнозе поступлений
A12: Вариант ответа | B12: Кол-во | C12: %
A15: E5: Эскалации в обход ДУП
A16: Вариант ответа | B16: Кол-во | C16: %
A19: C4: Продукт без пилота
A20: Вариант ответа | B20: Кол-во | C20: %
A23: G4: Часы на ручную отчётность
A24: Вариант ответа | B24: Кол-во | C24: %

Sheet ТОП боли
A1: Открытые ответы — боли, предложения, блокеры (для ручной кластеризации)
A2: Отфильтруйте столбец D (скрыть пустые) для просмотра только заполненных ответов
A3: Филиал | B3: ID вопроса | C3: Тема | D3: Цитата / ответ | E3: Категория (заполнить) | F3: Приоритет
A4: ='Сырые ответы'!B2 | B4: B11 | C4: Блокеры реализации | D4: =IF('Сырые ответы'!U2="","",'Сырые ответы'!U2)
A5: ='Сырые ответы'!B3 | B5: B11 | C5: Блокеры реализации | D5: =IF('Сырые ответы'!U3="","",'Сырые ответы'!U3)
A6: ='Сырые ответы'!B4 | B6: B11 | C6: Блокеры реализации | D6: =IF('Сырые ответы'!U4="","",'Сырые ответы'!U4)
A7: ='Сырые ответы'!B5 | B7: B11 | C7: Блокеры реализации | D7: =IF('Сырые ответы'!U5="","",'Сырые ответы'!U5)
A8: ='Сырые ответы'!B6 | B8: B11 | C8: Блокеры реализации | D8: =IF('Сырые ответы'!U6="","",'Сырые ответы'!U6)
A9: ='Сырые ответы'!B7 | B9: B11 | C9: Блокеры реализации | D9: =IF('Сырые ответы'!U7="","",'Сырые ответы'!U7)
A10: ='Сырые ответы'!B8 | B10: B11 | C10: Блокеры реализации | D10: =IF('Сырые ответы'!U8="","",'Сырые ответы'!U8)
A11: ='Сырые ответы'!B9 | B11: B11 | C11: Блокеры реализации | D11: =IF('Сырые ответы'!U9="","",'Сырые ответы'!U9)
A12: ='Сырые ответы'!B10 | B12: B11 | C12: Блокеры реализации | D12: =IF('Сырые ответы'!U10="","",'Сырые ответы'!U10)
A13: ='Сырые ответы'!B11 | B13: B11 | C13: Блокеры реализации | D13: =IF('Сырые ответы'!U11="","",'Сырые ответы'!U11)
A14: ='Сырые ответы'!B12 | B14: B11 | C14: Блокеры реализации | D14: =IF('Сырые ответы'!U12="","",'Сырые ответы'!U12)
A15: ='Сырые ответы'!B13 | B15: B11 | C15: Блокеры реализации | D15: =IF('Сырые ответы'!U13="","",'Сырые ответы'!U13)
... A53: ='Сырые ответы'!B51 | B53: B11 | C53: Блокеры реализации | D53: =IF('Сырые ответы'!U51="","",'Сырые ответы'!U51)
A54: ='Сырые ответы'!B2 | B54: C8 | C54: Боль сопровождения | D54: =IF('Сырые ответы'!AC2="","",'Сырые ответы'!AC2)
A55: ='Сырые ответы'!B3 | B55: C8 | C55: Боль сопровождения | D55: =IF('Сырые ответы'!AC3="","",'Сырые ответы'!AC3)
A56: ='Сырые ответы'!B4 | B56: C8 | C56: Боль сопровождения | D56: =IF('Сырые ответы'!AC4="","",'Сырые ответы'!AC4)
A57: ='Сырые ответы'!B5 | B57: C8 | C57: Боль сопровождения | D57: =IF('Сырые ответы'!AC5="","",'Сырые ответы'!AC5)
A58: ='Сырые ответы'!B6 | B58: C8 | C58: Боль сопровождения | D58: =IF('Сырые ответы'!AC6="","",'Сырые ответы'!AC6)
A59: ='Сырые ответы'!B7 | B59: C8 | C59: Боль сопровождения | D59: =IF('Сырые ответы'!AC7="","",'Сырые ответы'!AC7)
A60: ='Сырые ответы'!B8 | B60: C8 | C60: Боль сопровождения | D60: =IF('Сырые ответы'!AC8="","",'Сырые ответы'!AC8)
A61: ='Сырые ответы'!B9 | B61: C8 | C61: Боль сопровождения | D61: =IF('Сырые ответы'!AC9="","",'Сырые ответы'!AC9)
A62: ='Сырые ответы'!B10 | B62: C8 | C62: Боль сопровождения | D62: =IF('Сырые ответы'!AC10="","",'Сырые ответы'!AC10)
A63: ='Сырые ответы'!B11 | B63: C8 | C63: Боль сопровождения | D63: =IF('Сырые ответы'!AC11="","",'Сырые ответы'!AC11)
A64: ='Сырые ответы'!B12 | B64: C8 | C64: Боль сопровождения | D64: =IF('Сырые ответы'!AC12="","",'Сырые ответы'!AC12)
A65: ='Сырые ответы'!B13 | B65: C8 | C65: Боль сопровождения | D65: =IF('Сырые ответы'!AC13="","",'Сырые ответы'!AC13)
... A103: ='Сырые ответы'!B51 | B103: C8 | C103: Боль сопровождения | D103: =IF('Сырые ответы'!AC51="","",'Сырые ответы'!AC51)
A104: ='Сырые ответы'!B2 | B104: D8 | C104: Перерасход бюджета | D104: =IF('Сырые ответы'!AK2="","",'Сырые ответы'!AK2)
A105: ='Сырые ответы'!B3 | B105: D8 | C105: Перерасход бюджета | D105: =IF('Сырые ответы'!AK3="","",'Сырые ответы'!AK3)
A106: ='Сырые ответы'!B4 | B106: D8 | C106: Перерасход бюджета | D106: =IF('Сырые ответы'!AK4="","",'Сырые ответы'!AK4)
A107: ='Сырые ответы'!B5 | B107: D8 | C107: Перерасход бюджета | D107: =IF('Сырые ответы'!AK5="","",'Сырые ответы'!AK5)
A108: ='Сырые ответы'!B6 | B108: D8 | C108: Перерасход бюджета | D108: =IF('Сырые ответы'!AK6="","",'Сырые ответы'!AK6)
A109: ='Сырые ответы'!B7 | B109: D8 | C109: Перерасход бюджета | D109: =IF('Сырые ответы'!AK7="","",'Сырые ответы'!AK7)
A110: ='Сырые ответы'!B8 | B110: D8 | C110: Перерасход бюджета | D110: =IF('Сырые ответы'!AK8="","",'Сырые ответы'!AK8)
A111: ='Сырые ответы'!B9 | B111: D8 | C111: Перерасход бюджета | D111: =IF('Сырые ответы'!AK9="","",'Сырые ответы'!AK9)
A112: ='Сырые ответы'!B10 | B112: D8 | C112: Перерасход бюджета | D112: =IF('Сырые ответы'!AK10="","",'Сырые ответы'!AK10)
A113: ='Сырые ответы'!B11 | B113: D8 | C113: Перерасход бюджета | D113: =IF('Сырые ответы'!AK11="","",'Сырые ответы'!AK11)
A114: ='Сырые ответы'!B12 | B114: D8 | C114: Перерасход бюджета | D114: =IF('Сырые ответы'!AK12="","",'Сырые ответы'!AK12)
...

Sheet Интервью
A1: Кандидаты на углублённое интервью (H4 = Да / Возможно)
A2: Отфильтруйте столбец C: оставить «Да» и «Возможно, по согласованию»; сортировать по столбцу E (низкие оценки — приоритет)
A3: Филиал | B3: Должность | C3: Готовность к интервью | D3: Контакт | E3: Средняя оценка по шкалам | F3: Примечание
A4: ='Сырые ответы'!B2 | B4: ='Сырые ответы'!C2 | C4: ='Сырые ответы'!BM2 | D4: ='Сырые ответы'!BN2 | E4: =IF(COUNT('Сырые ответы'!AL2,'Сырые ответы'!AN2,'Сырые ответы'!X2,'Сырые ответы'!AE2,'Сырые ответы'!BG2)=0,"",AVERAGE('Сырые ответы'!AL2,'Сырые ответы'!AN2,'Сырые ответы'!X2,'Сырые ответы'!AE2,'Сырые ответы'!BG2))
A5: ='Сырые ответы'!B3 | B5: ='Сырые ответы'!C3 | C5: ='Сырые ответы'!BM3 | D5: ='Сырые ответы'!BN3 | E5: =IF(COUNT('Сырые ответы'!AL3,'Сырые ответы'!AN3,'Сырые ответы'!X3,'Сырые ответы'!AE3,'Сырые ответы'!BG3)=0,"",AVERAGE('Сырые ответы'!AL3,'Сырые ответы'!AN3,'Сырые ответы'!X3,'Сырые ответы'!AE3,'Сырые ответы'!BG3))
A6: ='Сырые ответы'!B4 | B6: ='Сырые ответы'!C4 | C6: ='Сырые ответы'!BM4 | D6: ='Сырые ответы'!BN4 | E6: =IF(COUNT('Сырые ответы'!AL4,'Сырые ответы'!AN4,'Сырые ответы'!X4,'Сырые ответы'!AE4,'Сырые ответы'!BG4)=0,"",AVERAGE('Сырые ответы'!AL4,'Сырые ответы'!AN4,'Сырые ответы'!X4,'Сырые ответы'!AE4,'Сырые ответы'!BG4))
A7: ='Сырые ответы'!B5 | B7: ='Сырые ответы'!C5 | C7: ='Сырые ответы'!BM5 | D7: ='Сырые ответы'!BN5 | E7: =IF(COUNT('Сырые ответы'!AL5,'Сырые ответы'!AN5,'Сырые ответы'!X5,'Сырые ответы'!AE5,'Сырые ответы'!BG5)=0,"",AVERAGE('Сырые ответы'!AL5,'Сырые ответы'!AN5,'Сырые ответы'!X5,'Сырые ответы'!AE5,'Сырые ответы'!BG5))
A8: ='Сырые ответы'!B6 | B8: ='Сырые ответы'!C6 | C8: ='Сырые ответы'!BM6 | D8: ='Сырые ответы'!BN6 | E8: =IF(COUNT('Сырые ответы'!AL6,'Сырые ответы'!AN6,'Сырые ответы'!X6,'Сырые ответы'!AE6,'Сырые ответы'!BG6)=0,"",AVERAGE('Сырые ответы'!AL6,'Сырые ответы'!AN6,'Сырые ответы'!X6,'Сырые ответы'!AE6,'Сырые ответы'!BG6))
A9: ='Сырые ответы'!B7 | B9: ='Сырые ответы'!C7 | C9: ='Сырые ответы'!BM7 | D9: ='Сырые ответы'!BN7 | E9: =IF(COUNT('Сырые ответы'!AL7,'Сырые ответы'!AN7,'Сырые ответы'!X7,'Сырые ответы'!AE7,'Сырые ответы'!BG7)=0,"",AVERAGE('Сырые ответы'!AL7,'Сырые ответы'!AN7,'Сырые ответы'!X7,'Сырые ответы'!AE7,'Сырые ответы'!BG7))
A10: ='Сырые ответы'!B8 | B10: ='Сырые ответы'!C8 | C10: ='Сырые ответы'!BM8 | D10: ='Сырые ответы'!BN8 | E10: =IF(COUNT('Сырые ответы'!AL8,'Сырые ответы'!AN8,'Сырые ответы'!X8,'Сырые ответы'!AE8,'Сырые ответы'!BG8)=0,"",AVERAGE('Сырые ответы'!AL8,'Сырые ответы'!AN8,'Сырые ответы'!X8,'Сырые ответы'!AE8,'Сырые ответы'!BG8))
A11: ='Сырые ответы'!B9 | B11: ='Сырые ответы'!C9 | C11: ='Сырые ответы'!BM9 | D11: ='Сырые ответы'!BN9 | E11: =IF(COUNT('Сырые ответы'!AL9,'Сырые ответы'!AN9,'Сырые ответы'!X9,'Сырые ответы'!AE9,'Сырые ответы'!BG9)=0,"",AVERAGE('Сырые ответы'!AL9,'Сырые ответы'!AN9,'Сырые ответы'!X9,'Сырые ответы'!AE9,'Сырые ответы'!BG9))
A12: ='Сырые ответы'!B10 | B12: ='Сырые ответы'!C10 | C12: ='Сырые ответы'!BM10 | D12: ='Сырые ответы'!BN10 | E12: =IF(COUNT('Сырые ответы'!AL10,'Сырые ответы'!AN10,'Сырые ответы'!X10,'Сырые ответы'!AE10,'Сырые ответы'!BG10)=0,"",AVERAGE('Сырые ответы'!AL10,'Сырые ответы'!AN10,'Сырые ответы'!X10,'Сырые ответы'!AE10,'Сырые ответы'!BG10))
A13: ='Сырые ответы'!B11 | B13: ='Сырые ответы'!C11 | C13: ='Сырые ответы'!BM11 | D13: ='Сырые ответы'!BN11 | E13: =IF(COUNT('Сырые ответы'!AL11,'Сырые ответы'!AN11,'Сырые ответы'!X11,'Сырые ответы'!AE11,'Сырые ответы'!BG11)=0,"",AVERAGE('Сырые ответы'!AL11,'Сырые ответы'!AN11,'Сырые ответы'!X11,'Сырые ответы'!AE11,'Сырые ответы'!BG11))
A14: ='Сырые ответы'!B12 | B14: ='Сырые ответы'!C12 | C14: ='Сырые ответы'!BM12 | D14: ='Сырые ответы'!BN12 | E14: =IF(COUNT('Сырые ответы'!AL12,'Сырые ответы'!AN12,'Сырые ответы'!X12,'Сырые ответы'!AE12,'Сырые ответы'!BG12)=0,"",AVERAGE('Сырые ответы'!AL12,'Сырые ответы'!AN12,'Сырые ответы'!X12,'Сырые ответы'!AE12,'Сырые ответы'!BG12))
A15: ='Сырые ответы'!B13 | B15: ='Сырые ответы'!C13 | C15: ='Сырые ответы'!BM13 | D15: ='Сырые ответы'!BN13 | E15: =IF(COUNT('Сырые ответы'!AL13,'Сырые ответы'!AN13,'Сырые ответы'!X13,'Сырые ответы'!AE13,'Сырые ответы'!BG13)=0,"",AVERAGE('Сырые ответы'!AL13,'Сырые ответы'!AN13,'Сырые ответы'!X13,'Сырые ответы'!AE13,'Сырые ответы'!BG13))
... A53: ='Сырые ответы'!B51 | B53: ='Сырые ответы'!C51 | C53: ='Сырые ответы'!BM51 | D53: ='Сырые ответы'!BN51 | E53: =IF(COUNT('Сырые ответы'!AL51,'Сырые ответы'!AN51,'Сырые ответы'!X51,'Сырые ответы'!AE51,'Сырые ответы'!BG51)=0,"",AVERAGE('Сырые ответы'!AL51,'Сырые ответы'!AN51,'Сырые ответы'!X51,'Сырые ответы'!AE51,'Сырые ответы'!BG51))
